Workbook

Sheet Special_Chart
I37: ="Month and Year" -> Month and Year | J37: ="# WO" -> # WO | K37: ="# late WO" -> # late WO | L37: ="% WO on Time" -> % WO on Time | M37: ="# samples" -> # samples | N37: ="# late samples" -> # late samples | O37: ="% sample on time" -> % sample on time
I38: =KPI_Special!A651 -> 07 2024 | J38: =KPI_Special!K651 -> 8 | K38: =KPI_Special!J651 -> 7 | L38: =KPI_Special!L651 -> 0.125 | M38: =KPI_Special!M651 -> 25 | N38: =KPI_Special!N651 -> 19 | O38: =KPI_Special!O651 -> 0.24
I39: =KPI_Special!A652 -> 08 2024 | J39: =KPI_Special!K652 -> 11 | K39: =KPI_Special!J652 -> 8 | L39: =KPI_Special!L652 -> 0.27272727 | M39: =KPI_Special!M652 -> 25 | N39: =KPI_Special!N652 -> 18 | O39: =KPI_Special!O652 -> 0.28
I40: =KPI_Special!A653 -> 09 2024 | J40: =KPI_Special!K653 -> 15 | K40: =KPI_Special!J653 -> 15 | L40: =KPI_Special!L653 -> 0 | M40: =KPI_Special!M653 -> 55 | N40: =KPI_Special!N653 -> 55 | O40: =KPI_Special!O653 -> 0
I41: =KPI_Special!A654 -> 10 2024 | J41: =KPI_Special!K654 -> 18 | K41: =KPI_Special!J654 -> 15 | L41: =KPI_Special!L654 -> 0.16666667 | M41: =KPI_Special!M654 -> 102 | N41: =KPI_Special!N654 -> 70 | O41: =KPI_Special!O654 -> 0.31372549
I42: =KPI_Special!A655 -> 11 2024 | J42: =KPI_Special!K655 -> 30 | K42: =KPI_Special!J655 -> 28 | L42: =KPI_Special!L655 -> 0.066666667 | M42: =KPI_Special!M655 -> 75 | N42: =KPI_Special!N655 -> 73 | O42: =KPI_Special!O655 -> 0.026666667
I43: =KPI_Special!A656 -> 12 2024 | J43: =KPI_Special!K656 -> 32 | K43: =KPI_Special!J656 -> 32 | L43: =KPI_Special!L656 -> 0 | M43: =KPI_Special!M656 -> 70 | N43: =KPI_Special!N656 -> 70 | O43: =KPI_Special!O656 -> 0
I44: =KPI_Special!A657 -> 01 2025 | J44: =KPI_Special!K657 -> 14 | K44: =KPI_Special!J657 -> 14 | L44: =KPI_Special!L657 -> 0 | M44: =KPI_Special!M657 -> 25 | N44: =KPI_Special!N657 -> 25 | O44: =KPI_Special!O657 -> 0
I45: =KPI_Special!A658 -> 02 2025 | J45: =KPI_Special!K658 -> 13 | K45: =KPI_Special!J658 -> 12 | L45: =KPI_Special!L658 -> 0.076923077 | M45: =KPI_Special!M658 -> 159 | N45: =KPI_Special!N658 -> 29 | O45: =KPI_Special!O658 -> 0.81761006
I46: =KPI_Special!A659 -> 03 2025 | J46: =KPI_Special!K659 -> 33 | K46: =KPI_Special!J659 -> 31 | L46: =KPI_Special!L659 -> 0.060606061 | M46: =KPI_Special!M659 -> 92 | N46: =KPI_Special!N659 -> 86 | O46: =KPI_Special!O659 -> 0.065217391
I47: =KPI_Special!A660 -> 04 2025 | J47: =KPI_Special!K660 -> 19 | K47: =KPI_Special!J660 -> 18 | L47: =KPI_Special!L660 -> 0.052631579 | M47: =KPI_Special!M660 -> 90 | N47: =KPI_Special!N660 -> 89 | O47: =KPI_Special!O660 -> 0.011111111
I48: =KPI_Special!A661 -> 05 2025 | J48: =KPI_Special!K661 -> 12 | K48: =KPI_Special!J661 -> 12 | L48: =KPI_Special!L661 -> 0 | M48: =KPI_Special!M661 -> 34 | N48: =KPI_Special!N661 -> 34 | O48: =KPI_Special!O661 -> 0
I49: =KPI_Special!A662 -> 06 2025 | J49: =KPI_Special!K662 -> 16 | K49: =KPI_Special!J662 -> 15 | L49: =KPI_Special!L662 -> 0.0625 | M49: =KPI_Special!M662 -> 30 | N49: =KPI_Special!N662 -> 29 | O49: =KPI_Special!O662 -> 0.033333333
... I63: =KPI_Special!A676 -> 08 2026 | J63: =KPI_Special!K676 -> 4 | K63: =KPI_Special!J676 -> 0 | L63: =KPI_Special!L676 -> 1 | M63: =KPI_Special!M676 -> 8 | N63: =KPI_Special!N676 -> 0 | O63: =KPI_Special!O676 -> 1
J64: =KPI_Special!K677 -> 410 | K64: =KPI_Special!J677 -> 361 | L64: =KPI_Special!L677 -> 0.1195122 | M64: =KPI_Special!M677 -> 1303 | N64: =KPI_Special!N677 -> 1024 | O64: =KPI_Special!O677 -> 0.21412126

Sheet Monthly_Chart
I37: ="Month and Year" -> Month and Year | J37: ="# WO" -> # WO | K37: ="# late WO" -> # late WO | L37: ="% WO on Time" -> % WO on Time | M37: ="# samples" -> # samples | N37: ="# late samples" -> # late samples | O37: ="% sample on time" -> % sample on time
I38: =KPI_Monthly!A625 -> 07 2024 | J38: =KPI_Monthly!K625 -> 4 | K38: =KPI_Monthly!J625 -> 1 | L38: =KPI_Monthly!L625 -> 0.75 | M38: =KPI_Monthly!M625 -> 142 | N38: =KPI_Monthly!N625 -> 4 | O38: =KPI_Monthly!O625 -> 0.97183099
I39: =KPI_Monthly!A626 -> 08 2024 | J39: =KPI_Monthly!K626 -> 22 | K39: =KPI_Monthly!J626 -> 13 | L39: =KPI_Monthly!L626 -> 0.40909091 | M39: =KPI_Monthly!M626 -> 366 | N39: =KPI_Monthly!N626 -> 216 | O39: =KPI_Monthly!O626 -> 0.40983607
I40: =KPI_Monthly!A627 -> 09 2024 | J40: =KPI_Monthly!K627 -> 16 | K40: =KPI_Monthly!J627 -> 14 | L40: =KPI_Monthly!L627 -> 0.125 | M40: =KPI_Monthly!M627 -> 354 | N40: =KPI_Monthly!N627 -> 119 | O40: =KPI_Monthly!O627 -> 0.66384181
I41: =KPI_Monthly!A628 -> 10 2024 | J41: =KPI_Monthly!K628 -> 25 | K41: =KPI_Monthly!J628 -> 14 | L41: =KPI_Monthly!L628 -> 0.44 | M41: =KPI_Monthly!M628 -> 384 | N41: =KPI_Monthly!N628 -> 213 | O41: =KPI_Monthly!O628 -> 0.4453125
I42: =KPI_Monthly!A629 -> 11 2024 | J42: =KPI_Monthly!K629 -> 15 | K42: =KPI_Monthly!J629 -> 11 | L42: =KPI_Monthly!L629 -> 0.26666667 | M42: =KPI_Monthly!M629 -> 383 | N42: =KPI_Monthly!N629 -> 144 | O42: =KPI_Monthly!O629 -> 0.62402089
I43: =KPI_Monthly!A630 -> 12 2024 | J43: =KPI_Monthly!K630 -> 27 | K43: =KPI_Monthly!J630 -> 23 | L43: =KPI_Monthly!L630 -> 0.14814815 | M43: =KPI_Monthly!M630 -> 352 | N43: =KPI_Monthly!N630 -> 228 | O43: =KPI_Monthly!O630 -> 0.35227273
I44: =KPI_Monthly!A631 -> 01 2025 | J44: =KPI_Monthly!K631 -> 14 | K44: =KPI_Monthly!J631 -> 12 | L44: =KPI_Monthly!L631 -> 0.14285714 | M44: =KPI_Monthly!M631 -> 318 | N44: =KPI_Monthly!N631 -> 85 | O44: =KPI_Monthly!O631 -> 0.7327044
I45: =KPI_Monthly!A632 -> 02 2025 | J45: =KPI_Monthly!K632 -> 17 | K45: =KPI_Monthly!J632 -> 16 | L45: =KPI_Monthly!L632 -> 0.058823529 | M45: =KPI_Monthly!M632 -> 326 | N45: =KPI_Monthly!N632 -> 212 | O45: =KPI_Monthly!O632 -> 0.34969325
I46: =KPI_Monthly!A633 -> 03 2025 | J46: =KPI_Monthly!K633 -> 11 | K46: =KPI_Monthly!J633 -> 10 | L46: =KPI_Monthly!L633 -> 0.090909091 | M46: =KPI_Monthly!M633 -> 336 | N46: =KPI_Monthly!N633 -> 188 | O46: =KPI_Monthly!O633 -> 0.44047619
I47: =KPI_Monthly!A634 -> 04 2025 | J47: =KPI_Monthly!K634 -> 17 | K47: =KPI_Monthly!J634 -> 15 | L47: =KPI_Monthly!L634 -> 0.11764706 | M47: =KPI_Monthly!M634 -> 335 | N47: =KPI_Monthly!N634 -> 96 | O47: =KPI_Monthly!O634 -> 0.71343284
I48: =KPI_Monthly!A635 -> 05 2025 | J48: =KPI_Monthly!K635 -> 8 | K48: =KPI_Monthly!J635 -> 6 | L48: =KPI_Monthly!L635 -> 0.25 | M48: =KPI_Monthly!M635 -> 337 | N48: =KPI_Monthly!N635 -> 89 | O48: =KPI_Monthly!O635 -> 0.73590504
I49: =KPI_Monthly!A636 -> 06 2025 | J49: =KPI_Monthly!K636 -> 10 | K49: =KPI_Monthly!J636 -> 7 | L49: =KPI_Monthly!L636 -> 0.3 | M49: =KPI_Monthly!M636 -> 322 | N49: =KPI_Monthly!N636 -> 90 | O49: =KPI_Monthly!O636 -> 0.72049689
... I63: =KPI_Monthly!A650 -> 08 2026 | J63: =KPI_Monthly!K650 -> 3 | K63: =KPI_Monthly!J650 -> 0 | L63: =KPI_Monthly!L650 -> 1 | M63: =KPI_Monthly!M650 -> 27 | N63: =KPI_Monthly!N650 -> 0 | O63: =KPI_Monthly!O650 -> 1
J64: =KPI_Monthly!K651 -> 384 | K64: =KPI_Monthly!J651 -> 265 | L64: =KPI_Monthly!L651 -> 0.30989583 | M64: =KPI_Monthly!M651 -> 8326 | N64: =KPI_Monthly!N651 -> 3292 | O64: =KPI_Monthly!O651 -> 0.60461206

Sheet KPI_Special
A3: Special KPI: 2024
A4: July
A6: Project Name | B6: Work Order | C6: Sample Period Ending | D6: Month and Year | E6: Sample Release Date | F6: Last Sample Rec. Date | G6: Report Due Date | H6: Report Type | I6: Late | J6: Count Of Late WO | K6: Count of WO | L6: Percent WO on Time | M6: Count Of Samples | N6: Count of Late Samples | O6: Percent Samp on Time | P6: Year | Q6: Month | R6: Month_Year | S6: Year_Range
A7: TSSP | B7: Q-8310 | C7: 45488 | D7: 07/2024 | E7: 08/13/2024 | F7: 07/29/2024 | G7: 45498 | H7: Special | I7: Late | J7: 1 | K7: 1 | L7: 0 | M7: 2 | N7: 2 | O7: 0 | P7: 2024 | Q7: July | R7: 072024 | S7: 2024 To 2026
A8: TSSP | B8: Q-8309 | C8: 45488 | D8: 07/2024 | E8: 08/13/2024 | F8: 07/29/2024 | G8: 45498 | H8: Special | I8: Late | J8: 1 | K8: 1 | L8: 0 | M8: 2 | N8: 2 | O8: 0 | P8: 2024 | Q8: July | R8: 072024 | S8: 2024 To 2026
A9: TSSP | B9: Q-8311 | C9: 45488 | D9: 07/2024 | E9: 08/13/2024 | F9: 07/19/2024 | G9: 45498 | H9: Special | I9: Late | J9: 1 | K9: 1 | L9: 0 | M9: 3 | N9: 3 | O9: 0 | P9: 2024 | Q9: July | R9: 072024 | S9: 2024 To 2026
A10: TSSP | B10: Q-8312 | C10: 45488 | D10: 07/2024 | E10: 08/21/2024 | F10: 07/22/2024 | G10: 45498 | H10: Special | I10: Late | J10: 1 | K10: 1 | L10: 0 | M10: 4 | N10: 4 | O10: 0 | P10: 2024 | Q10: July | R10: 072024 | S10: 2024 To 2026
A11: TSSP | B11: Q-8306 | C11: 45490 | D11: 07/2024 | E11: 08/05/2024 | F11: 07/22/2024 | G11: 45500 | H11: Special | I11: Late | J11: 1 | K11: 1 | L11: 0 | M11: 2 | N11: 2 | O11: 0 | P11: 2024 | Q11: July | R11: 072024 | S11: 2024 To 2026
A12: TSSP | B12: Q-8307 | C12: 45490 | D12: 07/2024 | E12: 08/05/2024 | F12: 07/22/2024 | G12: 45500 | H12: Special | I12: Late | J12: 1 | K12: 1 | L12: 0 | M12: 2 | N12: 2 | O12: 0 | P12: 2024 | Q12: July | R12: 072024 | S12: 2024 To 2026
A13: TSSP | B13: Q-8314 | C13: 45502 | D13: 07/2024 | E13: 08/07/2024 | F13: 08/02/2024 | G13: 45512 | H13: Special | J13: 0 | K13: 1 | L13: 1 | M13: 6 | N13: 0 | O13: 1 | P13: 2024 | Q13: July | R13: 072024 | S13: 2024 To 2026
A14: TSSP | B14: Q-8323 | C14: 45504 | D14: 07/2024 | E14: 08/21/2024 | F14: 08/05/2024 | G14: 45514 | H14: Special | I14: Late | J14: 1 | K14: 1 | L14: 0 | M14: 4 | N14: 4 | O14: 0 | P14: 2024 | Q14: July | R14: 072024 | S14: 2024 To 2026
I15: Totals: | J15: =SUM(J7:J14) -> 7 | K15: =SUM(K7:K14) -> 8 | L15: =(SUM(K7:K14) - SUM(J7:J14)) / SUM(K7:K14) -> 0.125 | M15: =SUM(M7:M14) -> 25 | N15: =SUM(N7:N14) -> 19 | O15: =(SUM(M7:M14) - SUM(N7:N14)) / SUM(M7:M14) -> 0.24
A20: Special KPI: 2024
A21: August
A23: Project Name | B23: Work Order | C23: Sample Period Ending | D23: Month and Year | E23: Sample Release Date | F23: Last Sample Rec. Date | G23: Report Due Date | H23: Report Type | I23: Late | J23: Count Of Late WO | K23: Count of WO | L23: Percent WO on Time | M23: Count Of Samples | N23: Count of Late Samples | O23: Percent Samp on Time | P23: Year | Q23: Month | R23: Month_Year | S23: Year_Range
A24: TSSP | B24: Q-8332 | C24: 45507 | D24: 08/2024 | E24: 08/13/2024 | F24: 08/07/2024 | G24: 45517 | H24: Special | J24: 0 | K24: 1 | L24: 1 | M24: 2 | N24: 0 | O24: 1 | P24: 2024 | Q24: August | R24: 082024 | S24: 2024 To 2026
A25: TSSP | B25: Q-8324 | C25: 45511 | D25: 08/2024 | E25: 08/27/2024 | F25: 08/16/2024 | G25: 45521 | H25: Special | I25: Late | J25: 1 | K25: 1 | L25: 0 | M25: 4 | N25: 4 | O25: 0 | P25: 2024 | Q25: August | R25: 082024 | S25: 2024 To 2026
A26: TSSP | B26: Q-8327 | C26: 45512 | D26: 08/2024 | E26: 09/10/2024 | F26: 08/22/2024 | G26: 45522 | H26: Special | I26: Late | J26: 1 | K26: 1 | L26: 0 | M26: 3 | N26: 3 | O26: 0 | P26: 2024 | Q26: August | R26: 082024 | S26: 2024 To 2026
A27: TSSP | B27: Q-8326 | C27: 45512 | D27: 08/2024 | E27: 09/06/2024 | F27: 08/19/2024 | G27: 45522 | H27: Special | I27: Late | J27: 1 | K27: 1 | L27: 0 | M27: 2 | N27: 2 | O27: 0 | P27: 2024 | Q27: August | R27: 082024 | S27: 2024 To 2026
A28: TSSP | B28: Q-8325 | C28: 45512 | D28: 08/2024 | E28: 09/06/2024 | F28: 08/22/2024 | G28: 45522 | H28: Special | I28: Late | J28: 1 | K28: 1 | L28: 0 | M28: 2 | N28: 2 | O28: 0 | P28: 2024 | Q28: August | R28: 082024 | S28: 2024 To 2026
A29: TSSP | B29: Q-8329 | C29: 45515 | D29: 08/2024 | E29: 08/27/2024 | F29: 08/16/2024 | G29: 45525 | H29: Special | I29: Late | J29: 1 | K29: 1 | L29: 0 | M29: 1 | N29: 1 | O29: 0 | P29: 2024 | Q29: August | R29: 082024 | S29: 2024 To 2026
A30: TSSP | B30: Q-8328 | C30: 45515 | D30: 08/2024 | E30: 08/21/2024 | F30: 08/15/2024 | G30: 45525 | H30: Special | J30: 0 | K30: 1 | L30: 1 | M30: 1 | N30: 0 | O30: 1 | P30: 2024 | Q30: August | R30: 082024 | S30: 2024 To 2026
A31: TSSP | B31: Q-8330 | C31: 45519 | D31: 08/2024 | E31: 08/27/2024 | F31: 08/16/2024 | G31: 45529 | H31: Special | I31: Late | J31: 1 | K31: 1 | L31: 0 | M31: 2 | N31: 2 | O31: 0 | P31: 2024 | Q31: August | R31: 082024 | S31: 2024 To 2026
A32: TSSP | B32: Q-8331 | C32: 45519 | D32: 08/2024 | E32: 08/27/2024 | F32: 08/16/2024 | G32: 45529 | H32: Special | I32: Late | J32: 1 | K32: 1 | L32: 0 | M32: 2 | N32: 2 | O32: 0 | P32: 2024 | Q32: August | R32: 082024 | S32: 2024 To 2026
A33: TSSP | B33: Q-8336 | C33: 45530 | D33: 08/2024 | E33: 09/23/2024 | F33: 09/03/2024 | G33: 45540 | H33: Special | I33: Late | J33: 1 | K33: 1 | L33: 0 | M33: 2 | N33: 2 | O33: 0 | P33: 2024 | Q33: August | R33: 082024 | S33: 2024 To 2026
A34: TSSP | B34: Q-8334 | C34: 45535 | D34: 08/2024 | E34: 08/21/2024 | F34: 08/09/2024 | G34: 45545 | H34: Special | J34: 0 | K34: 1 | L34: 1 | M34: 4 | N34: 0 | O34: 1 | P34: 2024 | Q34: August | R34: 082024 | S34: 2024 To 2026
I35: Totals: | J35: =SUM(J24:J34) -> 8 | K35: =SUM(K24:K34) -> 11 | L35: =(SUM(K24:K34) - SUM(J24:J34)) / SUM(K24:K34) -> 0.27272727 | M35: =SUM(M24:M34) -> 25 | N35: =SUM(N24:N34) -> 18 | O35: =(SUM(M24:M34) - SUM(N24:N34)) / SUM(M24:M34) -> 0.28
A40: Special KPI: 2024
A41: September
A43: Project Name | B43: Work Order | C43: Sample Period Ending | D43: Month and Year | E43: Sample Release Date | F43: Last Sample Rec. Date | G43: Report Due Date | H43: Report Type | I43: Late | J43: Count Of Late WO | K43: Count of WO | L43: Percent WO on Time | M43: Count Of Samples | N43: Count of Late Samples | O43: Percent Samp on Time | P43: Year | Q43: Month | R43: Month_Year | S43: Year_Range
A44: TSSP | B44: Q-8348 | C44: 45538 | D44: 09/2024 | E44: 09/23/2024 | F44: 09/09/2024 | G44: 45548 | H44: Special | I44: Late | J44: 1 | K44: 1 | L44: 0 | M44: 1 | N44: 1 | O44: 0 | P44: 2024 | Q44: September | R44: 092024 | S44: 2024 To 2026
A45: TSSP | B45: Q-8347 | C45: 45538 | D45: 09/2024 | E45: 09/27/2024 | F45: 09/17/2024 | G45: 45548 | H45: Special | I45: Late | J45: 1 | K45: 1 | L45: 0 | M45: 4 | N45: 4 | O45: 0 | P45: 2024 | Q45: September | R45: 092024 | S45: 2024 To 2026
A46: TSSP | B46: Q-8344 | C46: 45539 | D46: 09/2024 | E46: 09/23/2024 | F46: 09/10/2024 | G46: 45549 | H46: Special | I46: Late | J46: 1 | K46: 1 | L46: 0 | M46: 2 | N46: 2 | O46: 0 | P46: 2024 | Q46: September | R46: 092024 | S46: 2024 To 2026
A47: TSSP | B47: Q-8346 | C47: 45545 | D47: 09/2024 | E47: 09/25/2024 | F47: 09/10/2024 | G47: 45555 | H47: Special | I47: Late | J47: 1 | K47: 1 | L47: 0 | M47: 6 | N47: 6 | O47: 0 | P47: 2024 | Q47: September | R47: 092024 | S47: 2024 To 2026
A48: TSSP | B48: Q-8343 | C48: 45545 | D48: 09/2024 | E48: 09/26/2024 | F48: 09/17/2024 | G48: 45555 | H48: Special | I48: Late | J48: 1 | K48: 1 | L48: 0 | M48: 1 | N48: 1 | O48: 0 | P48: 2024 | Q48: September | R48: 092024 | S48: 2024 To 2026
A49: TSSP | B49: Q-8347 | C49: 45545 | D49: 09/2024 | E49: 09/27/2024 | F49: 09/17/2024 | G49: 45555 | H49: Special | I49: Late | J49: 1 | K49: 1 | L49: 0 | M49: 5 | N49: 5 | O49: 0 | P49: 2024 | Q49: September | R49: 092024 | S49: 2024 To 2026
A50: TSSP | B50: Q-8355 | C50: 45550 | D50: 09/2024 | E50: 10/14/2024 | F50: 09/24/2024 | G50: 45560 | H50: Special | I50: Late | J50: 1 | K50: 1 | L50: 0 | M50: 12 | N50: 12 | O50: 0 | P50: 2024 | Q50: September | R50: 092024 | S50: 2024 To 2026
A51: TSSP | B51: Q-8345 | C51: 45550 | D51: 09/2024 | E51: 09/27/2024 | F51: 09/23/2024 | G51: 45560 | H51: Special | I51: Late | J51: 1 | K51: 1 | L51: 0 | M51: 2 | N51: 2 | O51: 0 | P51: 2024 | Q51: September | R51: 092024 | S51: 2024 To 2026
A52: TSSP | B52: Q-8353 | C52: 45550 | D52: 09/2024 | E52: 10/14/2024 | F52: 09/24/2024 | G52: 45560 | H52: Special | I52: Late | J52: 1 | K52: 1 | L52: 0 | M52: 2 | N52: 2 | O52: 0 | P52: 2024 | Q52: September | R52: 092024 | S52: 2024 To 2026
A53: TSSP | B53: Q-8354 | C53: 45550 | D53: 09/2024 | E53: 09/27/2024 | F53: 09/19/2024 | G53: 45560 | H53: Special | I53: Late | J53: 1 | K53: 1 | L53: 0 | M53: 2 | N53: 2 | O53: 0 | P53: 2024 | Q53: September | R53: 092024 | S53: 2024 To 2026
...

Sheet KPI_Monthly
A3: Monthly KPI: 2024
A4: July
A6: Project Name | B6: Work Order | C6: Sample Period Ending | D6: Month and Year | E6: Sample Release Date | F6: Last Sample Rec. Date | G6: Report Due Date | H6: Report Type | I6: Late | J6: Count Of Late WO | K6: Count of WO | L6: Percent WO on Time | M6: Count Of Samples | N6: Count of Late Samples | O6: Percent Samp on Time | P6: Year | Q6: Month | R6: Month_Year | S6: Year_Range | T6: Calculated | U6: Calculated
A7: TSSS | B7: Q-8296 | C7: 45487 | D7: 07/2024 | E7: 8/12/2024 | F7: 08/05/2024 | G7: 45516 | H7: Monthy | J7: 0 | K7: 1 | L7: 1 | M7: 135 | N7: 0 | O7: 1 | P7: 2024 | Q7: July | R7: 072024 | S7: 2024 To 2026 | T7: =SUMIFS($J$1:INDEX(J:J,ROW()-1),$I$1:INDEX(I:I,ROW()-1),"<>Totals:") -> 0 | U7: =SUMIFS($M$1:INDEX(M:M,ROW()),$I$1:INDEX(I:I,ROW()),"<>*Totals:*") -> 135
A8: TSTG | B8: Q-8292 | C8: 45488 | D8: 07/2024 | E8: 03/05/2025 | F8: 07/29/2024 | G8: 45517 | H8: Monthy | I8: Late | J8: 1 | K8: 1 | L8: 0 | M8: 4 | N8: 4 | O8: 0 | P8: 2024 | Q8: July | R8: 072024 | S8: 2024 To 2026 | T8: =SUMIFS($J$1:INDEX(J:J,ROW()-1),$I$1:INDEX(I:I,ROW()-1),"<>Totals:") -> 0 | U8: =SUMIFS($M$1:INDEX(M:M,ROW()),$I$1:INDEX(I:I,ROW()),"<>*Totals:*") -> 139
A9: TSSD | B9: Q-8292 | C9: 45488 | D9: 07/2024 | E9: 08/13/2024 | F9: 07/29/2024 | G9: 45517 | H9: Monthy | J9: 0 | K9: 1 | L9: 1 | M9: 1 | N9: 0 | O9: 1 | P9: 2024 | Q9: July | R9: 072024 | S9: 2024 To 2026 | T9: =SUMIFS($J$1:INDEX(J:J,ROW()-1),$I$1:INDEX(I:I,ROW()-1),"<>Totals:") -> 1 | U9: =SUMIFS($M$1:INDEX(M:M,ROW()),$I$1:INDEX(I:I,ROW()),"<>*Totals:*") -> 140
A10: TSTD | B10: Q-8291.3 | C10: 45489 | D10: 07/2024 | E10: 08/13/2024 | F10: 07/16/2024 | G10: 45518 | H10: Monthy | J10: 0 | K10: 1 | L10: 1 | M10: 2 | N10: 0 | O10: 1 | P10: 2024 | Q10: July | R10: 072024 | S10: 2024 To 2026 | T10: =SUMIFS($J$1:INDEX(J:J,ROW()-1),$I$1:INDEX(I:I,ROW()-1),"<>Totals:") -> 1 | U10: =SUMIFS($M$1:INDEX(M:M,ROW()),$I$1:INDEX(I:I,ROW()),"<>*Totals:*") -> 142
I11: Totals: | J11: =SUM(J7:J10) -> 1 | K11: =SUM(K7:K10) -> 4 | L11: =(SUM(K7:K10) - SUM(J7:J10)) / SUM(K7:K10) -> 0.75 | M11: =SUM(M7:M10) -> 142 | N11: =SUM(N7:N10) -> 4 | O11: =(SUM(M7:M10) - SUM(N7:N10)) / SUM(M7:M10) -> 0.97183099
I12: Run. Count of Late WO | L12: Run. Count of Samp.
I13: 1 | L13: 142
A16: Monthly KPI: 2024
A17: August
A19: Project Name | B19: Work Order | C19: Sample Period Ending | D19: Month and Year | E19: Sample Release Date | F19: Last Sample Rec. Date | G19: Report Due Date | H19: Report Type | I19: Late | J19: Count Of Late WO | K19: Count of WO | L19: Percent WO on Time | M19: Count Of Samples | N19: Count of Late Samples | O19: Percent Samp on Time | P19: Year | Q19: Month | R19: Month_Year | S19: Year_Range | T19: Calculated | U19: Calculated
A20: TSTD | B20: Q-8315 | C20: 45505 | D20: 08/2024 | E20: 09/10/2024 | F20: 08/23/2024 | G20: 45534 | H20: Monthy | I20: Late | J20: 1 | K20: 1 | L20: 0 | M20: 20 | N20: 20 | O20: 0 | P20: 2024 | Q20: August | R20: 082024 | S20: 2024 To 2026 | T20: =SUMIFS($J$1:INDEX(J:J,ROW()-1),$I$1:INDEX(I:I,ROW()-1),"<>Totals:") -> 1 | U20: =SUMIFS($M$1:INDEX(M:M,ROW()),$I$1:INDEX(I:I,ROW()),"<>*Totals:*") -> 162
A21: TSIV | B21: Q-8319.1 | C21: 45505 | D21: 08/2024 | E21: 09/10/2024 | F21: 08/26/2024 | G21: 45534 | H21: Monthy | I21: Late | J21: 1 | K21: 1 | L21: 0 | M21: 10 | N21: 10 | O21: 0 | P21: 2024 | Q21: August | R21: 082024 | S21: 2024 To 2026 | T21: =SUMIFS($J$1:INDEX(J:J,ROW()-1),$I$1:INDEX(I:I,ROW()-1),"<>Totals:") -> 2 | U21: =SUMIFS($M$1:INDEX(M:M,ROW()),$I$1:INDEX(I:I,ROW()),"<>*Totals:*") -> 172
A22: TSTE | B22: Q-8317 | C22: 45505 | D22: 08/2024 | E22: 09/10/2024 | F22: 08/26/2024 | G22: 45534 | H22: Monthy | I22: Late | J22: 1 | K22: 1 | L22: 0 | M22: 17 | N22: 17 | O22: 0 | P22: 2024 | Q22: August | R22: 082024 | S22: 2024 To 2026 | T22: =SUMIFS($J$1:INDEX(J:J,ROW()-1),$I$1:INDEX(I:I,ROW()-1),"<>Totals:") -> 3 | U22: =SUMIFS($M$1:INDEX(M:M,ROW()),$I$1:INDEX(I:I,ROW()),"<>*Totals:*") -> 189
A23: TSTE | B23: Q-8317.1 | C23: 45505 | D23: 08/2024 | E23: 09/10/2024 | F23: 08/22/2024 | G23: 45534 | H23: Monthy | I23: Late | J23: 1 | K23: 1 | L23: 0 | M23: 9 | N23: 9 | O23: 0 | P23: 2024 | Q23: August | R23: 082024 | S23: 2024 To 2026 | T23: =SUMIFS($J$1:INDEX(J:J,ROW()-1),$I$1:INDEX(I:I,ROW()-1),"<>Totals:") -> 4 | U23: =SUMIFS($M$1:INDEX(M:M,ROW()),$I$1:INDEX(I:I,ROW()),"<>*Totals:*") -> 198
A24: TSSD | B24: Q-8316 | C24: 45513 | D24: 08/2024 | E24: 09/17/2024 | F24: 09/10/2024 | G24: 45542 | H24: Monthy | I24: Late | J24: 1 | K24: 1 | L24: 0 | M24: 28 | N24: 28 | O24: 0 | P24: 2024 | Q24: August | R24: 082024 | S24: 2024 To 2026 | T24: =SUMIFS($J$1:INDEX(J:J,ROW()-1),$I$1:INDEX(I:I,ROW()-1),"<>Totals:") -> 5 | U24: =SUMIFS($M$1:INDEX(M:M,ROW()),$I$1:INDEX(I:I,ROW()),"<>*Totals:*") -> 226
A25: TSTG | B25: Q-8316 | C25: 45513 | D25: 08/2024 | E25: 03/05/2025 | F25: 09/12/2024 | G25: 45542 | H25: Monthy | I25: Late | J25: 1 | K25: 1 | L25: 0 | M25: 94 | N25: 94 | O25: 0 | P25: 2024 | Q25: August | R25: 082024 | S25: 2024 To 2026 | T25: =SUMIFS($J$1:INDEX(J:J,ROW()-1),$I$1:INDEX(I:I,ROW()-1),"<>Totals:") -> 6 | U25: =SUMIFS($M$1:INDEX(M:M,ROW()),$I$1:INDEX(I:I,ROW()),"<>*Totals:*") -> 320
A26: TSIF | B26: Q-8318 | C26: 45513 | D26: 08/2024 | E26: 09/03/2024 | F26: 08/15/2024 | G26: 45542 | H26: Monthy | J26: 0 | K26: 1 | L26: 1 | M26: 5 | N26: 0 | O26: 1 | P26: 2024 | Q26: August | R26: 082024 | S26: 2024 To 2026 | T26: =SUMIFS($J$1:INDEX(J:J,ROW()-1),$I$1:INDEX(I:I,ROW()-1),"<>Totals:") -> 7 | U26: =SUMIFS($M$1:INDEX(M:M,ROW()),$I$1:INDEX(I:I,ROW()),"<>*Totals:*") -> 325
A27: TSTH | B27: Q-8321 | C27: 45513 | D27: 08/2024 | E27: 09/03/2024 | F27: 08/15/2024 | G27: 45542 | H27: Monthy | J27: 0 | K27: 1 | L27: 1 | M27: 12 | N27: 0 | O27: 1 | P27: 2024 | Q27: August | R27: 082024 | S27: 2024 To 2026 | T27: =SUMIFS($J$1:INDEX(J:J,ROW()-1),$I$1:INDEX(I:I,ROW()-1),"<>Totals:") -> 7 | U27: =SUMIFS($M$1:INDEX(M:M,ROW()),$I$1:INDEX(I:I,ROW()),"<>*Totals:*") -> 337
A28: TSSS | B28: Q-8320 | C28: 45516 | D28: 08/2024 | E28: 9/10/2024 | F28: 08/30/2024 | G28: 45545 | H28: Monthy | J28: 0 | K28: 1 | L28: 1 | M28: 123 | N28: 0 | O28: 1 | P28: 2024 | Q28: August | R28: 082024 | S28: 2024 To 2026 | T28: =SUMIFS($J$1:INDEX(J:J,ROW()-1),$I$1:INDEX(I:I,ROW()-1),"<>Totals:") -> 7 | U28: =SUMIFS($M$1:INDEX(M:M,ROW()),$I$1:INDEX(I:I,ROW()),"<>*Totals:*") -> 460
A29: TSTG | B29: Q-8316 | C29: 45516 | D29: 08/2024 | E29: 03/05/2025 | F29: 09/12/2024 | G29: 45545 | H29: Monthy | I29: Late | J29: 1 | K29: 1 | L29: 0 | M29: 3 | N29: 3 | O29: 0 | P29: 2024 | Q29: August | R29: 082024 | S29: 2024 To 2026 | T29: =SUMIFS($J$1:INDEX(J:J,ROW()-1),$I$1:INDEX(I:I,ROW()-1),"<>Totals:") -> 7 | U29: =SUMIFS($M$1:INDEX(M:M,ROW()),$I$1:INDEX(I:I,ROW()),"<>*Totals:*") -> 463
A30: TSSD | B30: Q-8316 | C30: 45516 | D30: 08/2024 | E30: 09/17/2024 | F30: 09/10/2024 | G30: 45545 | H30: Monthy | I30: Late | J30: 1 | K30: 1 | L30: 0 | M30: 1 | N30: 1 | O30: 0 | P30: 2024 | Q30: August | R30: 082024 | S30: 2024 To 2026 | T30: =SUMIFS($J$1:INDEX(J:J,ROW()-1),$I$1:INDEX(I:I,ROW()-1),"<>Totals:") -> 8 | U30: =SUMIFS($M$1:INDEX(M:M,ROW()),$I$1:INDEX(I:I,ROW()),"<>*Totals:*") -> 464
A31: TSSS | B31: Q-8320.1 | C31: 45516 | D31: 08/2024 | E31: 03/05/2025 | F31: 08/14/2024 | G31: 45545 | H31: Monthy | I31: Late | J31: 1 | K31: 1 | L31: 0 | M31: 8 | N31: 8 | O31: 0 | P31: 2024 | Q31: August | R31: 082024 | S31: 2024 To 2026 | T31: =SUMIFS($J$1:INDEX(J:J,ROW()-1),$I$1:INDEX(I:I,ROW()-1),"<>Totals:") -> 9 | U31: =SUMIFS($M$1:INDEX(M:M,ROW()),$I$1:INDEX(I:I,ROW()),"<>*Totals:*") -> 472
A32: TSTE | B32: Q-8317.2 | C32: 45518 | D32: 08/2024 | E32: 09/10/2024 | F32: 08/19/2024 | G32: 45547 | H32: Monthy | J32: 0 | K32: 1 | L32: 1 | M32: 1 | N32: 0 | O32: 1 | P32: 2024 | Q32: August | R32: 082024 | S32: 2024 To 2026 | T32: =SUMIFS($J$1:INDEX(J:J,ROW()-1),$I$1:INDEX(I:I,ROW()-1),"<>Totals:") -> 10 | U32: =SUMIFS($M$1:INDEX(M:M,ROW()),$I$1:INDEX(I:I,ROW()),"<>*Totals:*") -> 473
A33: TSIV | B33: Q-8319.2 | C33: 45518 | D33: 08/2024 | E33: 09/10/2024 | F33: 08/28/2024 | G33: 45547 | H33: Monthy | J33: 0 | K33: 1 | L33: 1 | M33: 1 | N33: 0 | O33: 1 | P33: 2024 | Q33: August | R33: 082024 | S33: 2024 To 2026 | T33: =SUMIFS($J$1:INDEX(J:J,ROW()-1),$I$1:INDEX(I:I,ROW()-1),"<>Totals:") -> 10 | U33: =SUMIFS($M$1:INDEX(M:M,ROW()),$I$1:INDEX(I:I,ROW()),"<>*Totals:*") -> 474
A34: TSTE | B34: Q-8317.2 | C34: 45523 | D34: 08/2024 | E34: 09/10/2024 | F34: 08/19/2024 | G34: 45552 | H34: Monthy | J34: 0 | K34: 1 | L34: 1 | M34: 1 | N34: 0 | O34: 1 | P34: 2024 | Q34: August | R34: 082024 | S34: 2024 To 2026 | T34: =SUMIFS($J$1:INDEX(J:J,ROW()-1),$I$1:INDEX(I:I,ROW()-1),"<>Totals:") -> 10 | U34: =SUMIFS($M$1:INDEX(M:M,ROW()),$I$1:INDEX(I:I,ROW()),"<>*Totals:*") -> 475
A35: TSTG | B35: Q-8316 | C35: 45525 | D35: 08/2024 | E35: 03/05/2025 | F35: 09/12/2024 | G35: 45554 | H35: Monthy | I35: Late | J35: 1 | K35: 1 | L35: 0 | M35: 11 | N35: 11 | O35: 0 | P35: 2024 | Q35: August | R35: 082024 | S35: 2024 To 2026 | T35: =SUMIFS($J$1:INDEX(J:J,ROW()-1),$I$1:INDEX(I:I,ROW()-1),"<>Totals:") -> 10 | U35: =SUMIFS($M$1:INDEX(M:M,ROW()),$I$1:INDEX(I:I,ROW()),"<>*Totals:*") -> 486
A36: TSSD | B36: Q-8316 | C36: 45525 | D36: 08/2024 | E36: 09/17/2024 | F36: 09/10/2024 | G36: 45554 | H36: Monthy | J36: 0 | K36: 1 | L36: 1 | M36: 4 | N36: 0 | O36: 1 | P36: 2024 | Q36: August | R36: 082024 | S36: 2024 To 2026 | T36: =SUMIFS($J$1:INDEX(J:J,ROW()-1),$I$1:INDEX(I:I,ROW()-1),"<>Totals:") -> 11 | U36: =SUMIFS($M$1:INDEX(M:M,ROW()),$I$1:INDEX(I:I,ROW()),"<>*Totals:*") -> 490
A37: TSSS | B37: Q-8320 | C37: 45526 | D37: 08/2024 | E37: 03/05/2025 | F37: 08/30/2024 | G37: 45555 | H37: Monthy | I37: Late | J37: 1 | K37: 1 | L37: 0 | M37: 3 | N37: 3 | O37: 0 | P37: 2024 | Q37: August | R37: 082024 | S37: 2024 To 2026 | T37: =SUMIFS($J$1:INDEX(J:J,ROW()-1),$I$1:INDEX(I:I,ROW()-1),"<>Totals:") -> 11 | U37: =SUMIFS($M$1:INDEX(M:M,ROW()),$I$1:INDEX(I:I,ROW()),"<>*Totals:*") -> 493
A38: TSIV | B38: Q-8319.2 | C38: 45532 | D38: 08/2024 | E38: 09/10/2024 | F38: 08/28/2024 | G38: 45561 | H38: Monthy | J38: 0 | K38: 1 | L38: 1 | M38: 1 | N38: 0 | O38: 1 | P38: 2024 | Q38: August | R38: 082024 | S38: 2024 To 2026 | T38: =SUMIFS($J$1:INDEX(J:J,ROW()-1),$I$1:INDEX(I:I,ROW()-1),"<>Totals:") -> 12 | U38: =SUMIFS($M$1:INDEX(M:M,ROW()),$I$1:INDEX(I:I,ROW()),"<>*Totals:*") -> 494
A39: TSSD | B39: Q-8316 | C39: 45534 | D39: 08/2024 | E39: 09/17/2024 | F39: 09/10/2024 | G39: 45563 | H39: Monthy | J39: 0 | K39: 1 | L39: 1 | M39: 2 | N39: 0 | O39: 1 | P39: 2024 | Q39: August | R39: 082024 | S39: 2024 To 2026 | T39: =SUMIFS($J$1:INDEX(J:J,ROW()-1),$I$1:INDEX(I:I,ROW()-1),"<>Totals:") -> 12 | U39: =SUMIFS($M$1:INDEX(M:M,ROW()),$I$1:INDEX(I:I,ROW()),"<>*Totals:*") -> 496
A40: TSTG | B40: Q-8316 | C40: 45534 | D40: 08/2024 | E40: 03/05/2025 | F40: 09/12/2024 | G40: 45563 | H40: Monthy | I40: Late | J40: 1 | K40: 1 | L40: 0 | M40: 6 | N40: 6 | O40: 0 | P40: 2024 | Q40: August | R40: 082024 | S40: 2024 To 2026 | T40: =SUMIFS($J$1:INDEX(J:J,ROW()-1),$I$1:INDEX(I:I,ROW()-1),"<>Totals:") -> 12 | U40: =SUMIFS($M$1:INDEX(M:M,ROW()),$I$1:INDEX(I:I,ROW()),"<>*Totals:*") -> 502
A41: TSSS | B41: Q-8320 | C41: 45535 | D41: 08/2024 | E41: 03/05/2025 | F41: 08/30/2024 | G41: 45564 | H41: Monthy | I41: Late | J41: 1 | K41: 1 | L41: 0 | M41: 6 | N41: 6 | O41: 0 | P41: 2024 | Q41: August | R41: 082024 | S41: 2024 To 2026 | T41: =SUMIFS($J$1:INDEX(J:J,ROW()-1),$I$1:INDEX(I:I,ROW()-1),"<>Totals:") -> 13 | U41: =SUMIFS($M$1:INDEX(M:M,ROW()),$I$1:INDEX(I:I,ROW()),"<>*Totals:*") -> 508
I42: Totals: | J42: =SUM(J20:J41) -> 13 | K42: =SUM(K20:K41) -> 22 | L42: =(SUM(K20:K41) - SUM(J20:J41)) / SUM(K20:K41) -> 0.40909091 | M42: =SUM(M20:M41) -> 366 | N42: =SUM(N20:N41) -> 216 | O42: =(SUM(M20:M41) - SUM(N20:N41)) / SUM(M20:M41) -> 0.40983607
I43: Run. Count of Late WO | L43: Run. Count of Samp.
I44: 13 | L44: 508
A47: Monthly KPI: 2024
A48: September
...
